### App Versions
```
{
	"erpnext": "14.19.0",
	"frappe": "14.29.0",
	"payments": "0.0.1",
	"shipstation_integration": "0.0.1"
}
```
### Route
```
List/Error Log/List
```
### Traceback
```
Traceback (most recent call last):
  File "apps/frappe/frappe/app.py", line 66, in application
    response = frappe.api.handle()
  File "apps/frappe/frappe/api.py", line 54, in handle
    return frappe.handler.handle()
  File "apps/frappe/frappe/handler.py", line 45, in handle
    data = execute_cmd(cmd)
  File "apps/frappe/frappe/handler.py", line 83, in execute_cmd
    return frappe.call(method, **frappe.form_dict)
  File "apps/frappe/frappe/__init__.py", line 1607, in call
    return fn(*args, **newargs)
  File "apps/frappe/frappe/client.py", line 131, in get_value
    value = get_list(
  File "apps/frappe/frappe/client.py", line 66, in get_list
    frappe.error_log("get_list_client", str(result_json))
  File "env/lib/python3.10/site-packages/werkzeug/local.py", line 570, in <lambda>
    __call__ = _ProxyLookup(lambda self, *args, **kwargs: self(*args, **kwargs))
TypeError: 'list' object is not callable

```
### Request Data
```
{
	"type": "GET",
	"args": {
		"doctype": "Logs To Clear",
		"fieldname": "days",
		"filters": "{\"ref_doctype\":\"Error Log\"}",
		"parent": "Log Settings"
	},
	"headers": {},
	"error_handlers": {},
	"url": "/api/method/frappe.client.get_value"
}
```
### Response Data
```
{
	"exception": "TypeError: 'list' object is not callable"
}
```